Workbook
Name ColumnTitle1: Expense3[[#Headers],[Date]]
Name ColumnTitle1: #REF!
Name Mileage_Total: Expense3[[#Totals],[Mileage/KM]]
Name Mileage_Total: #REF!
Name Reimbursement_Total: Expense3[[#Totals],[Reimbursement]]
Name Reimbursement_Total: #REF!
Name RowTitleRegion1..C6: 'Statement of Work'!#REF!
Name RowTitleRegion1..C6: #REF!
Name RowTitleRegion2..E6: 'Statement of Work'!#REF!
Name RowTitleRegion2..E6: #REF!

Sheet Statement of Work
B2: Province | C2: Saskatchewan | D2: Billing Details | H2: Total | J2: =J16 -> 1282.605
B4: Date | C4: Expense Category | D4: Description | E4: Notes | F4: Quantity | G4: Rate | H4: Hours | I4: Mileage/KM | J4: Reimbursement
B5: April 1 2022 | C5: SOS Inventory Creation | D5: =IF(TRUE,(VLOOKUP(C5,'Hidden Doc'!$D$20:$F$33,2,TRUE)),(VLOOKUP(C5,'Hidden Doc'!$D$20:$F$33,3,TRUE))) -> Service On Site - attendance for inventory creation and documentation | G5: 69 | H5: 5 | J5: =IF(VLOOKUP(C5,'Hidden Doc'!H24:H29,1,TRUE)=C5,Expense3[[#This Row],[Rate]]*Expense3[[#This Row],[Hours]],IF(VLOOKUP(C5,'Hidden Doc'!K24,1,TRUE)=C5,Expense3[[#This Row],[Rate]]*Expense3[[#This Row],[Mileage/KM]],IF(VLOOKUP(C5,'Hidden Doc'!H38:H45,1,TRUE)=C5,Expense3[[#This Row],[Rate]]))) -> 345
B6: April 1 2022 | C6: Mileage | D6: =IF(TRUE,(VLOOKUP(C6,'Hidden Doc'!$D$20:$F$33,2,TRUE)),(VLOOKUP(C6,'Hidden Doc'!$D$20:$F$33,3,TRUE))) -> Exceeds 50Km Round Trip | G6: 0.89 | I6: 200 | J6: =IF(VLOOKUP(C6,'Hidden Doc'!H24:H29,1,TRUE)=C6,Expense3[[#This Row],[Rate]]*Expense3[[#This Row],[Hours]],IF(VLOOKUP(C6,'Hidden Doc'!K24,1,TRUE)=C6,Expense3[[#This Row],[Rate]]*Expense3[[#This Row],[Mileage/KM]],IF(VLOOKUP(C6,'Hidden Doc'!H38:H45,1,TRUE)=C6,Expense3[[#This Row],[Rate]]))) -> 178
B7: April 1 2022 | C7: Receipt Tracking/Recoverable Depreciation Reconciliation | D7: =IF(TRUE,(VLOOKUP(C7,'Hidden Doc'!$D$20:$F$33,2,TRUE)),(VLOOKUP(C7,'Hidden Doc'!$D$20:$F$33,3,TRUE))) -> Available upon request | G7: 69 | H7: 2.5 | J7: =IF(VLOOKUP(C7,'Hidden Doc'!H24:H29,1,TRUE)=C7,Expense3[[#This Row],[Rate]]*Expense3[[#This Row],[Hours]],IF(VLOOKUP(C7,'Hidden Doc'!K24,1,TRUE)=C7,Expense3[[#This Row],[Rate]]*Expense3[[#This Row],[Mileage/KM]],IF(VLOOKUP(C7,'Hidden Doc'!H38:H45,1,TRUE)=C7,Expense3[[#This Row],[Rate]]))) -> 172.5
B8: April 1 2022 | C8: Extended Daily Expenses | D8: =IF(TRUE,(VLOOKUP(C8,'Hidden Doc'!$D$20:$F$33,2,TRUE)),(VLOOKUP(C8,'Hidden Doc'!$D$20:$F$33,3,TRUE))) -> Per Diem Per Appraiser | F8: =IFERROR(VLOOKUP(C8,'Hidden Doc'!H41:H45,1,0),G8) -> 650 | G8: 650
B9: April 1 2022 | C9: Select Specialty | D9: =IF(TRUE,(VLOOKUP(C9,'Hidden Doc'!$D$20:$F$33,2,TRUE)),(VLOOKUP(C9,'Hidden Doc'!$D$20:$F$33,3,TRUE))) -> Specialty Valuation-for items requiring expertise | G9: 50 | J9: =IF(VLOOKUP(C9,'Hidden Doc'!H24:H29,1,TRUE)=C9,Expense3[[#This Row],[Rate]]*Expense3[[#This Row],[Hours]],IF(VLOOKUP(C9,'Hidden Doc'!K24,1,TRUE)=C9,Expense3[[#This Row],[Rate]]*Expense3[[#This Row],[Mileage/KM]],IF(VLOOKUP(C9,'Hidden Doc'!H38:H45,1,TRUE)=C9,Expense3[[#This Row],[Rate]]))) -> 50
B10: April 1 2022 | C10: Post Claim Modifications | D10: =IF(TRUE,(VLOOKUP(C10,'Hidden Doc'!$D$20:$F$33,2,TRUE)),(VLOOKUP(C10,'Hidden Doc'!$D$20:$F$33,3,TRUE))) -> Post Claim Processing and adjustments on request, if necessary | G10: 69 | H10: 4 | J10: =IF(VLOOKUP(C10, 'Hidden Doc'!H24:H29,1,TRUE)=C10,Expense3[[#This Row],[Rate]]*Expense3[[#This Row],[Hours]],IF(VLOOKUP(C10, 'Hidden Doc'!K24,1,TRUE)=C10,Expense3[[#This Row],[Rate]]*Expense3[[#This Row],[Mileage/KM]],IF(VLOOKUP(C10, 'Hidden Doc'!H38:H45,1,TRUE)=C10,Expense3[[#This Row],[Rate]]))) -> 276
B11: April 1 2022 | C11: PPE & Supplies | D11: =IF(TRUE,(VLOOKUP(C11,'Hidden Doc'!$D$20:$F$33,2,TRUE)),(VLOOKUP(C11,'Hidden Doc'!$D$20:$F$33,3,TRUE))) -> P100 Combo Filter - 1 x $60 ea, Tyvek Coveralls - 1 x $15 ea, Nitrile Glove - 1 x $2 pr, N95 Mask - 1 x $5 ea, | G11: 84 | J11: =IF(VLOOKUP(C11, 'Hidden Doc'!H24:H29,1,TRUE)=C11,Expense3[[#This Row],[Rate]]*Expense3[[#This Row],[Hours]],IF(VLOOKUP(C11, 'Hidden Doc'!K24,1,TRUE)=C11,Expense3[[#This Row],[Rate]]*Expense3[[#This Row],[Mileage/KM]],IF(VLOOKUP(C11, 'Hidden Doc'!H38:H45,1,TRUE)=C11,Expense3[[#This Row],[Rate]]))) -> 84
B12: April 1 2022 | C12: Rental Car/Parking/Tolls | D12: =IF(TRUE,(VLOOKUP(C12,'Hidden Doc'!$D$20:$F$33,2,TRUE)),(VLOOKUP(C12,'Hidden Doc'!$D$20:$F$33,3,TRUE))) -> Submitted Receipts value only | G12: 50 | J12: =IF(VLOOKUP(C12, 'Hidden Doc'!H24:H29,1,TRUE)=C12,Expense3[[#This Row],[Rate]]*Expense3[[#This Row],[Hours]],IF(VLOOKUP(C12, 'Hidden Doc'!K24,1,TRUE)=C12,Expense3[[#This Row],[Rate]]*Expense3[[#This Row],[Mileage/KM]],IF(VLOOKUP(C12, 'Hidden Doc'!H38:H45,1,TRUE)=C12,Expense3[[#This Row],[Rate]]))) -> 50
B13: Special Notes: | H13: SUBTOTAL | I13: =IFERROR(IF(OR(ISBLANK(G13),ISBLANK(H13)),0,H13-G13), "") -> 0 | J13: =SUM(J5:J12) -> 1155.5
H14: PST | I14: =VLOOKUP(C2,'Hidden Doc'!$H$6:$I$18,2,FALSE)/100 -> 0.06 | J14: =SUM(J13*I14) -> 69.33
H15: GST/HST | I15: =VLOOKUP(C2,'Hidden Doc'!$K$6:$L$18,2,FALSE)/100 -> 0.05 | J15: =SUM(J13*I15) -> 57.775
H16: TOTAL | J16: =SUM(J13,J14,J15) -> 1282.605

Sheet Hidden Doc
D5: REP NAME | E5: PHONE | H5: PROVINCE | I5: PST | K5: PROVINCE | L5: HST/GST
D6: Andre Bourgoin-Horne | E6: 438-223-3609 | H6: Alberta | I6: 0 | K6: Alberta | L6: 5
D7: Andrew Widdowson | E7: 416-498-3777 | H7: British Columbia | I7: 7 | K7: British Columbia | L7: 5
D8: Arpitha Ravishankar | E8: 437-900-6252 | H8: Manitoba | I8: 7 | K8: Manitoba | L8: 5
D9: Edgar Nieva | E9: 306-502-2136 | H9: New Brunswick | I9: 0 | K9: New Brunswick | L9: 15
D10: Genevieve Aube | E10: 438-920-0342 | H10: Newfoundland and Labrador | I10: 0 | K10: Newfoundland and Labrador | L10: 15
D11: Italia Martinez | E11: 289-921-9242 | H11: Nova Scotia | I11: 0 | K11: Nova Scotia | L11: 15
D12: Natalija Palacolo | E12: 289-659-5184 | H12: Ontario | I12: 0 | K12: Ontario | L12: 13
D13: Rida Rizvi | E13: 416-498-2970 | H13: Prince Edward Island | I13: 0 | K13: Prince Edward Island | L13: 15
D14: Sarah York | E14: 587-921-5398 | H14: Quebec | I14: 9.975 | K14: Quebec | L14: 5
D15: Stewart Tarrant | E15: 437-774-3658 | H15: Saskatchewan | I15: 6 | K15: Saskatchewan | L15: 5
H16: Northwest Territories | I16: 0 | K16: Northwest Territories | L16: 5
H17: Nunavut | I17: 0 | K17: Nunavut | L17: 5
D18: SOW REFERENCE | H18: Yukon | I18: 0 | K18: Yukon | L18: 5
D19: EXPENSE CATEGORY | E19: DESCRIPTION
D20: Accommodation | E20: Submitted Receipts value only | F20: Blank
D21: Airfare | E21: Submitted Receipts value only | F21: Blank
D22: Extended Daily Expenses | E22: Per Diem Per Appraiser | F22: Blank
D23: List Assist/Reporting and Communications | E23: Listing and working with policy holder including labelling and generation of the SOL and all reports | F23: Blank | H23: Rate*Hour | K23: Rate*Mileage
D24: Mileage | E24: Exceeds 50Km Round Trip | F24: Blank | H24: Appraisal Estimate | K24: Mileage
D25: Miscellaneous | E25: Submitted Receipts value only | F25: Blank | H25: List Assist/Reporting and Communications
D26: Post Claim Modifications | E26: Post Claim Processing and adjustments on request, if necessary | F26: Blank | H26: Post Claim Modifications
D27: PPE & Supplies | E27: P100 Combo Filter - 1 x $60 ea, Tyvek Coveralls - 1 x $15 ea, Nitrile Glove - 1 x $2 pr, N95 Mask - 1 x $5 ea, | F27: Blank | H27: Receipt Tracking/Recoverable Depreciation Reconciliation
D28: Receipt Tracking/Recoverable Depreciation Reconciliation | E28: Available upon request | F28: Blank | H28: SOS Inventory Creation
D29: Rental Car/Parking/Tolls | E29: Submitted Receipts value only | F29: Blank | H29: Travel Time
D30: Select Specialty | E30: Specialty Valuation-for items requiring expertise | F30: Blank
D31: Single Day Expense | E31: On-site expenses | F31: Blank
D32: SOS Inventory Creation | E32: Service On Site - attendance for inventory creation and documentation | F32: Blank
D33: Travel Time | E33: Round Trip Travel Time | F33: Blank
D36: FEE BUDGET REFERENCE
D37: EXPENSE CATEGORY | E37: DESCRIPTION | H37: Rate Direct
D38: Accommodation | E38: Submitted Receipts value only | F38: Blank | H38: Accommodation
D39: Airfare | E39: Submitted Receipts value only | F39: Blank | H39: Airfare
D40: Appraisal Estimate | E40: Total number of estimated lines at $0.00 per line. | F40: Blank | H40: Extended Daily Expenses
D41: Extended Daily Expenses | E41: Per Diem Per Appraiser | F41: Blank | H41: Miscellaneous
D42: List Assist/Reporting and Communications | E42: Listing and working with policy holder including labelling and generation of the SOL and all reports | F42: Blank | H42: PPE & Supplies
D43: Mileage | E43: Exceeds 50Km Round Trip | F43: Blank | H43: Rental Car/Parking/Tolls
D44: Miscellaneous | E44: Submitted Receipts value only | F44: Blank | H44: Select Specialty
D45: Post Claim Modifications | E45: Post Claim Processing and adjustments on request, if necessary | F45: Blank | H45: Single Day Expense
D46: PPE & Supplies | E46: P100 Combo Filter - 1 x $60 ea, Tyvek Coveralls - 1 x $15 ea, Nitrile Glove - 1 x $2 pr, N95 Mask - 1 x $5 ea, | F46: Blank
...
